<?xml version="1.0" encoding="UTF-8"?>
<!-- Generated by org.testng.reporters.JUnitReportReporter -->
<testsuite hostname="DESKTOP-CB1PK7K" failures="1" tests="5" name="mavenAndTestNG.hrm.login.LoginTests" time="23.063" errors="0" timestamp="2022-12-04T09:10:49 CST" skipped="0">
  <testcase classname="mavenAndTestNG.hrm.login.LoginTests" name="verify_user_is_not_able_to_login_invalid_credentials" time="4.177"/>
  <system-out/>
  <testcase classname="mavenAndTestNG.hrm.login.LoginTests" name="test_Login_Functionality_Is_Working" time="5.812">
    <failure message="expected [Welcome ggg] but found [Welcome Yoll]" type="java.lang.AssertionError">
      <![CDATA[java.lang.AssertionError: expected [Welcome ggg] but found [Welcome Yoll]
at org.testng.Assert.fail(Assert.java:99)
at org.testng.Assert.failNotEquals(Assert.java:1037)
at org.testng.Assert.assertEqualsImpl(Assert.java:140)
at org.testng.Assert.assertEquals(Assert.java:122)
at org.testng.Assert.assertEquals(Assert.java:629)
at org.testng.Assert.assertEquals(Assert.java:639)
at mavenAndTestNG.hrm.login.LoginTests.test_Login_Functionality_Is_Working(LoginTests.java:88)
at java.base/jdk.internal.reflect.DirectMethodHandleAccessor.invoke(DirectMethodHandleAccessor.java:104)
at java.base/java.lang.reflect.Method.invoke(Method.java:577)
at org.testng.internal.MethodInvocationHelper.invokeMethod(MethodInvocationHelper.java:133)
at org.testng.internal.TestInvoker.invokeMethod(TestInvoker.java:598)
at org.testng.internal.TestInvoker.invokeTestMethod(TestInvoker.java:173)
at org.testng.internal.MethodRunner.runInSequence(MethodRunner.java:46)
at org.testng.internal.TestInvoker$MethodInvocationAgent.invoke(TestInvoker.java:824)
at org.testng.internal.TestInvoker.invokeTestMethods(TestInvoker.java:146)
at org.testng.internal.TestMethodWorker.invokeTestMethods(TestMethodWorker.java:146)
at org.testng.internal.TestMethodWorker.run(TestMethodWorker.java:128)
at java.base/java.util.ArrayList.forEach(ArrayList.java:1511)
at org.testng.TestRunner.privateRun(TestRunner.java:794)
at org.testng.TestRunner.run(TestRunner.java:596)
at org.testng.SuiteRunner.runTest(SuiteRunner.java:377)
at org.testng.SuiteRunner.runSequentially(SuiteRunner.java:371)
at org.testng.SuiteRunner.privateRun(SuiteRunner.java:332)
at org.testng.SuiteRunner.run(SuiteRunner.java:276)
at org.testng.SuiteRunnerWorker.runSuite(SuiteRunnerWorker.java:53)
at org.testng.SuiteRunnerWorker.run(SuiteRunnerWorker.java:96)
at org.testng.TestNG.runSuitesSequentially(TestNG.java:1212)
at org.testng.TestNG.runSuitesLocally(TestNG.java:1134)
at org.testng.TestNG.runSuites(TestNG.java:1063)
at org.testng.TestNG.run(TestNG.java:1031)
at com.intellij.rt.testng.IDEARemoteTestNG.run(IDEARemoteTestNG.java:66)
at com.intellij.rt.testng.RemoteTestNGStarter.main(RemoteTestNGStarter.java:109)
]]>
    </failure>
  </testcase> <!-- test_Login_Functionality_Is_Working -->
  <system-out/>
  <testcase classname="mavenAndTestNG.hrm.login.LoginTests" name="verify_user_is_not_able_to_login_invalid_credentials" time="4.293"/>
  <system-out/>
  <testcase classname="mavenAndTestNG.hrm.login.LoginTests" name="verify_user_is_not_able_to_login_invalid_credentials" time="3.795"/>
  <system-out/>
  <testcase classname="mavenAndTestNG.hrm.login.LoginTests" name="verify_user_is_not_able_to_login_invalid_credentials" time="4.986"/>
  <system-out/>
</testsuite> <!-- mavenAndTestNG.hrm.login.LoginTests -->
